[2020-07-18 17:46:26,829] {taskinstance.py:670} INFO - Dependencies all met for <TaskInstance: etl_preprocessing.preprocess_test 2020-07-18T21:44:39.261561+00:00 [queued]>
[2020-07-18 17:46:26,838] {taskinstance.py:670} INFO - Dependencies all met for <TaskInstance: etl_preprocessing.preprocess_test 2020-07-18T21:44:39.261561+00:00 [queued]>
[2020-07-18 17:46:26,838] {taskinstance.py:880} INFO - 
--------------------------------------------------------------------------------
[2020-07-18 17:46:26,838] {taskinstance.py:881} INFO - Starting attempt 1 of 1
[2020-07-18 17:46:26,838] {taskinstance.py:882} INFO - 
--------------------------------------------------------------------------------
[2020-07-18 17:46:26,843] {taskinstance.py:901} INFO - Executing <Task(DockerOperator): preprocess_test> on 2020-07-18T21:44:39.261561+00:00
[2020-07-18 17:46:26,845] {standard_task_runner.py:54} INFO - Started process 47880 to run task
[2020-07-18 17:46:26,870] {standard_task_runner.py:77} INFO - Running: ['airflow', 'run', 'etl_preprocessing', 'preprocess_test', '2020-07-18T21:44:39.261561+00:00', '--job_id', '73', '--pool', 'default_pool', '--raw', '-sd', 'DAGS_FOLDER/elt_preprocessing.py', '--cfg_path', '/var/folders/00/80wjhvv115lcj4bckmhhb8x40000gn/T/tmpqt3yubi5']
[2020-07-18 17:46:26,871] {standard_task_runner.py:78} INFO - Job 73: Subtask preprocess_test
[2020-07-18 17:46:26,895] {logging_mixin.py:112} INFO - Running %s on host %s <TaskInstance: etl_preprocessing.preprocess_test 2020-07-18T21:44:39.261561+00:00 [running]> 1.0.0.0.0.0.0.0.0.0.0.0.0.0.0.0.0.0.0.0.0.0.0.0.0.0.0.0.0.0.0.0.ip6.arpa
[2020-07-18 17:46:27,018] {docker_operator.py:210} INFO - Starting docker container from image feature_selection_web:latest
[2020-07-18 17:46:27,599] {docker_operator.py:243} INFO - Input Notebook:  notebooks/feature_selection.ipynb
Output Notebook: notebooks/output/code_exec_111111.ipynb
[2020-07-18 17:46:28,488] {docker_operator.py:243} INFO - Executing notebook with kernel: venv-kensho-feature-selection
Executing Cell 1---------------------------------------
[2020-07-18 17:46:28,512] {docker_operator.py:243} INFO - Ending Cell 1------------------------------------------
[2020-07-18 17:46:28,524] {docker_operator.py:243} INFO - Executing Cell 2---------------------------------------
[2020-07-18 17:46:28,543] {docker_operator.py:243} INFO - name of the variable:docker.for.mac.host.internal
[2020-07-18 17:46:28,544] {docker_operator.py:243} INFO - Ending Cell 2------------------------------------------
[2020-07-18 17:46:28,557] {docker_operator.py:243} INFO - Executing Cell 3---------------------------------------
[2020-07-18 17:46:28,568] {docker_operator.py:243} INFO - Ending Cell 3------------------------------------------
[2020-07-18 17:46:28,579] {docker_operator.py:243} INFO - Executing Cell 4---------------------------------------
[2020-07-18 17:46:28,603] {docker_operator.py:243} INFO - '/'
[2020-07-18 17:46:28,607] {docker_operator.py:243} INFO - Ending Cell 4------------------------------------------
[2020-07-18 17:46:28,622] {docker_operator.py:243} INFO - Executing Cell 5---------------------------------------
[2020-07-18 17:46:28,634] {docker_operator.py:243} INFO - Ending Cell 5------------------------------------------
[2020-07-18 17:46:28,647] {docker_operator.py:243} INFO - Executing Cell 6---------------------------------------
[2020-07-18 17:46:28,660] {docker_operator.py:243} INFO - Ending Cell 6------------------------------------------
[2020-07-18 17:46:28,672] {docker_operator.py:243} INFO - Executing Cell 7---------------------------------------
[2020-07-18 17:46:29,372] {docker_operator.py:243} INFO - Ending Cell 7------------------------------------------
[2020-07-18 17:46:29,386] {docker_operator.py:243} INFO - Executing Cell 8---------------------------------------
[2020-07-18 17:46:29,399] {docker_operator.py:243} INFO - Ending Cell 8------------------------------------------
[2020-07-18 17:46:29,410] {docker_operator.py:243} INFO - Executing Cell 9---------------------------------------
[2020-07-18 17:46:29,435] {docker_operator.py:243} INFO - Ending Cell 9------------------------------------------
[2020-07-18 17:46:29,447] {docker_operator.py:243} INFO - Executing Cell 10--------------------------------------
[2020-07-18 17:46:29,461] {docker_operator.py:243} INFO - Ending Cell 10-----------------------------------------
[2020-07-18 17:46:29,473] {docker_operator.py:243} INFO - Executing Cell 11--------------------------------------
[2020-07-18 17:46:29,984] {docker_operator.py:243} INFO - docker.for.mac.host.internal
[2020-07-18 17:46:30,089] {docker_operator.py:243} INFO - Ending Cell 11-----------------------------------------
[2020-07-18 17:46:30,103] {docker_operator.py:243} INFO - Executing Cell 12--------------------------------------
[2020-07-18 17:46:30,117] {docker_operator.py:243} INFO - Ending Cell 12-----------------------------------------
[2020-07-18 17:46:30,129] {docker_operator.py:243} INFO - Executing Cell 13--------------------------------------
[2020-07-18 17:46:30,170] {docker_operator.py:243} INFO - name of the variable inside function:docker.for.mac.host.internal
[2020-07-18 17:46:30,173] {docker_operator.py:243} INFO - Ending Cell 13-----------------------------------------
[2020-07-18 17:46:30,187] {docker_operator.py:243} INFO - Executing Cell 14--------------------------------------
[2020-07-18 17:46:30,200] {docker_operator.py:243} INFO - Ending Cell 14-----------------------------------------
[2020-07-18 17:46:30,213] {docker_operator.py:243} INFO - Executing Cell 15--------------------------------------
[2020-07-18 17:46:30,273] {docker_operator.py:243} INFO - Ending Cell 15-----------------------------------------
[2020-07-18 17:46:30,287] {docker_operator.py:243} INFO - Executing Cell 16--------------------------------------
[2020-07-18 17:46:30,310] {docker_operator.py:243} INFO - Ending Cell 16-----------------------------------------
[2020-07-18 17:46:30,324] {docker_operator.py:243} INFO - Executing Cell 17--------------------------------------
[2020-07-18 17:46:30,350] {docker_operator.py:243} INFO - THIS IS THE://notebooks/
[2020-07-18 17:46:30,461] {docker_operator.py:243} INFO - Ending Cell 17-----------------------------------------
[2020-07-18 17:46:31,899] {docker_operator.py:243} INFO - Traceback (most recent call last):
  File "/usr/local/bin/papermill", line 8, in <module>
    sys.exit(papermill())
  File "/usr/local/lib/python3.7/site-packages/click/core.py", line 829, in __call__
    return self.main(*args, **kwargs)
  File "/usr/local/lib/python3.7/site-packages/click/core.py", line 782, in main
    rv = self.invoke(ctx)
  File "/usr/local/lib/python3.7/site-packages/click/core.py", line 1066, in invoke
    return ctx.invoke(self.callback, **ctx.params)
  File "/usr/local/lib/python3.7/site-packages/click/core.py", line 610, in invoke
    return callback(*args, **kwargs)
  File "/usr/local/lib/python3.7/site-packages/papermill/cli.py", line 238, in papermill
    execution_timeout=execution_timeout,
  File "/usr/local/lib/python3.7/site-packages/papermill/execute.py", line 110, in execute_notebook
    raise_for_execution_errors(nb, output_path)
  File "/usr/local/lib/python3.7/site-packages/papermill/execute.py", line 222, in raise_for_execution_errors
    raise error
papermill.exceptions.PapermillExecutionError: 
---------------------------------------------------------------------------
Exception encountered at "In [10]":
---------------------------------------------------------------------------
FileNotFoundError                         Traceback (most recent call last)
<ipython-input-10-0622cca218be> in <module>
     16         pickle.dump(le,handle,protocol=pickle.HIGHEST_PROTOCOL)
     17 elif opt=='test':
---> 18     with open(path+'label_encoder.p','rb') as handle:
     19         le = pickle.load(handle)
     20     l=le.transform(labels)

FileNotFoundError: [Errno 2] No such file or directory: '//notebooks/label_encoder.p'
[2020-07-18 17:46:33,106] {taskinstance.py:1150} ERROR - docker container failed: {'Error': None, 'StatusCode': 1}
Traceback (most recent call last):
  File "/Users/mendes/miniconda3/envs/venv-kensho/lib/python3.7/site-packages/airflow/models/taskinstance.py", line 984, in _run_raw_task
    result = task_copy.execute(context=context)
  File "/Users/mendes/miniconda3/envs/venv-kensho/lib/python3.7/site-packages/airflow/operators/docker_operator.py", line 277, in execute
    return self._run_image()
  File "/Users/mendes/miniconda3/envs/venv-kensho/lib/python3.7/site-packages/airflow/operators/docker_operator.py", line 247, in _run_image
    raise AirflowException('docker container failed: ' + repr(result))
airflow.exceptions.AirflowException: docker container failed: {'Error': None, 'StatusCode': 1}
[2020-07-18 17:46:33,108] {taskinstance.py:1194} INFO - Marking task as FAILED. dag_id=etl_preprocessing, task_id=preprocess_test, execution_date=20200718T214439, start_date=20200718T214626, end_date=20200718T214633
[2020-07-18 17:46:33,117] {configuration.py:338} WARNING - section/key [smtp/smtp_user] not found in config
[2020-07-18 17:46:33,118] {configuration.py:338} WARNING - section/key [smtp/smtp_user] not found in config
[2020-07-18 17:46:33,119] {taskinstance.py:1200} ERROR - Failed to send email to: ['info@example.com']
[2020-07-18 17:46:33,120] {taskinstance.py:1201} ERROR - [Errno 61] Connection refused
Traceback (most recent call last):
  File "/Users/mendes/miniconda3/envs/venv-kensho/lib/python3.7/site-packages/airflow/models/taskinstance.py", line 984, in _run_raw_task
    result = task_copy.execute(context=context)
  File "/Users/mendes/miniconda3/envs/venv-kensho/lib/python3.7/site-packages/airflow/operators/docker_operator.py", line 277, in execute
    return self._run_image()
  File "/Users/mendes/miniconda3/envs/venv-kensho/lib/python3.7/site-packages/airflow/operators/docker_operator.py", line 247, in _run_image
    raise AirflowException('docker container failed: ' + repr(result))
airflow.exceptions.AirflowException: docker container failed: {'Error': None, 'StatusCode': 1}

During handling of the above exception, another exception occurred:

Traceback (most recent call last):
  File "/Users/mendes/miniconda3/envs/venv-kensho/lib/python3.7/site-packages/airflow/models/taskinstance.py", line 1473, in email_alert
    send_email(self.task.email, subject, html_content)
  File "/Users/mendes/miniconda3/envs/venv-kensho/lib/python3.7/site-packages/airflow/utils/email.py", line 62, in send_email
    mime_subtype=mime_subtype, mime_charset=mime_charset, **kwargs)
  File "/Users/mendes/miniconda3/envs/venv-kensho/lib/python3.7/site-packages/airflow/utils/email.py", line 108, in send_email_smtp
    send_MIME_email(smtp_mail_from, recipients, msg, dryrun)
  File "/Users/mendes/miniconda3/envs/venv-kensho/lib/python3.7/site-packages/airflow/utils/email.py", line 127, in send_MIME_email
    s = smtplib.SMTP_SSL(SMTP_HOST, SMTP_PORT) if SMTP_SSL else smtplib.SMTP(SMTP_HOST, SMTP_PORT)
  File "/Users/mendes/miniconda3/envs/venv-kensho/lib/python3.7/smtplib.py", line 251, in __init__
    (code, msg) = self.connect(host, port)
  File "/Users/mendes/miniconda3/envs/venv-kensho/lib/python3.7/smtplib.py", line 336, in connect
    self.sock = self._get_socket(host, port, self.timeout)
  File "/Users/mendes/miniconda3/envs/venv-kensho/lib/python3.7/smtplib.py", line 307, in _get_socket
    self.source_address)
  File "/Users/mendes/miniconda3/envs/venv-kensho/lib/python3.7/socket.py", line 728, in create_connection
    raise err
  File "/Users/mendes/miniconda3/envs/venv-kensho/lib/python3.7/socket.py", line 716, in create_connection
    sock.connect(sa)
ConnectionRefusedError: [Errno 61] Connection refused

During handling of the above exception, another exception occurred:

Traceback (most recent call last):
  File "/Users/mendes/miniconda3/envs/venv-kensho/lib/python3.7/site-packages/airflow/models/taskinstance.py", line 1198, in handle_failure
    self.email_alert(error)
  File "/Users/mendes/miniconda3/envs/venv-kensho/lib/python3.7/site-packages/airflow/models/taskinstance.py", line 1475, in email_alert
    send_email(self.task.email, subject, html_content_err)
  File "/Users/mendes/miniconda3/envs/venv-kensho/lib/python3.7/site-packages/airflow/utils/email.py", line 62, in send_email
    mime_subtype=mime_subtype, mime_charset=mime_charset, **kwargs)
  File "/Users/mendes/miniconda3/envs/venv-kensho/lib/python3.7/site-packages/airflow/utils/email.py", line 108, in send_email_smtp
    send_MIME_email(smtp_mail_from, recipients, msg, dryrun)
  File "/Users/mendes/miniconda3/envs/venv-kensho/lib/python3.7/site-packages/airflow/utils/email.py", line 127, in send_MIME_email
    s = smtplib.SMTP_SSL(SMTP_HOST, SMTP_PORT) if SMTP_SSL else smtplib.SMTP(SMTP_HOST, SMTP_PORT)
  File "/Users/mendes/miniconda3/envs/venv-kensho/lib/python3.7/smtplib.py", line 251, in __init__
    (code, msg) = self.connect(host, port)
  File "/Users/mendes/miniconda3/envs/venv-kensho/lib/python3.7/smtplib.py", line 336, in connect
    self.sock = self._get_socket(host, port, self.timeout)
  File "/Users/mendes/miniconda3/envs/venv-kensho/lib/python3.7/smtplib.py", line 307, in _get_socket
    self.source_address)
  File "/Users/mendes/miniconda3/envs/venv-kensho/lib/python3.7/socket.py", line 728, in create_connection
    raise err
  File "/Users/mendes/miniconda3/envs/venv-kensho/lib/python3.7/socket.py", line 716, in create_connection
    sock.connect(sa)
ConnectionRefusedError: [Errno 61] Connection refused
[2020-07-18 17:46:36,827] {local_task_job.py:102} INFO - Task exited with return code 1
