[2020-07-18 16:00:21,308] {taskinstance.py:670} INFO - Dependencies all met for <TaskInstance: etl_preprocessing.raw-to-db 2020-07-18T19:58:34.228234+00:00 [queued]>
[2020-07-18 16:00:21,316] {taskinstance.py:670} INFO - Dependencies all met for <TaskInstance: etl_preprocessing.raw-to-db 2020-07-18T19:58:34.228234+00:00 [queued]>
[2020-07-18 16:00:21,317] {taskinstance.py:880} INFO - 
--------------------------------------------------------------------------------
[2020-07-18 16:00:21,317] {taskinstance.py:881} INFO - Starting attempt 1 of 1
[2020-07-18 16:00:21,317] {taskinstance.py:882} INFO - 
--------------------------------------------------------------------------------
[2020-07-18 16:00:21,322] {taskinstance.py:901} INFO - Executing <Task(DockerOperator): raw-to-db> on 2020-07-18T19:58:34.228234+00:00
[2020-07-18 16:00:21,324] {standard_task_runner.py:54} INFO - Started process 38638 to run task
[2020-07-18 16:00:21,349] {standard_task_runner.py:77} INFO - Running: ['airflow', 'run', 'etl_preprocessing', 'raw-to-db', '2020-07-18T19:58:34.228234+00:00', '--job_id', '40', '--pool', 'default_pool', '--raw', '-sd', 'DAGS_FOLDER/elt_preprocessing.py', '--cfg_path', '/var/folders/00/80wjhvv115lcj4bckmhhb8x40000gn/T/tmpsr9ogsx8']
[2020-07-18 16:00:21,350] {standard_task_runner.py:78} INFO - Job 40: Subtask raw-to-db
[2020-07-18 16:00:21,373] {logging_mixin.py:112} INFO - Running %s on host %s <TaskInstance: etl_preprocessing.raw-to-db 2020-07-18T19:58:34.228234+00:00 [running]> 1.0.0.0.0.0.0.0.0.0.0.0.0.0.0.0.0.0.0.0.0.0.0.0.0.0.0.0.0.0.0.0.ip6.arpa
[2020-07-18 16:00:21,471] {docker_operator.py:210} INFO - Starting docker container from image raw_to_db:latest
[2020-07-18 16:00:22,054] {docker_operator.py:243} INFO - Input Notebook:  notebooks/raw_to_sql.ipynb
Output Notebook: notebooks/output/raw_to_sql_exec_111111.ipynb
[2020-07-18 16:00:22,949] {docker_operator.py:243} INFO - Executing notebook with kernel: venv-kensho-raw-to-db
Executing Cell 1---------------------------------------
[2020-07-18 16:00:22,962] {docker_operator.py:243} INFO - Ending Cell 1------------------------------------------
[2020-07-18 16:00:22,972] {docker_operator.py:243} INFO - Executing Cell 2---------------------------------------
[2020-07-18 16:00:22,982] {docker_operator.py:243} INFO - Ending Cell 2------------------------------------------
[2020-07-18 16:00:22,993] {docker_operator.py:243} INFO - Executing Cell 3---------------------------------------
[2020-07-18 16:00:23,003] {docker_operator.py:243} INFO - Ending Cell 3------------------------------------------
[2020-07-18 16:00:23,013] {docker_operator.py:243} INFO - Executing Cell 4---------------------------------------
[2020-07-18 16:00:23,316] {docker_operator.py:243} INFO - Ending Cell 4------------------------------------------
[2020-07-18 16:00:23,327] {docker_operator.py:243} INFO - Executing Cell 5---------------------------------------
[2020-07-18 16:00:23,337] {docker_operator.py:243} INFO - Ending Cell 5------------------------------------------
[2020-07-18 16:00:23,348] {docker_operator.py:243} INFO - Executing Cell 6---------------------------------------
[2020-07-18 16:00:23,359] {docker_operator.py:243} INFO - Ending Cell 6------------------------------------------
[2020-07-18 16:00:23,369] {docker_operator.py:243} INFO - Executing Cell 7---------------------------------------
[2020-07-18 16:00:23,380] {docker_operator.py:243} INFO - Ending Cell 7------------------------------------------
[2020-07-18 16:00:23,390] {docker_operator.py:243} INFO - Executing Cell 8---------------------------------------
[2020-07-18 16:00:23,409] {docker_operator.py:243} INFO - Ending Cell 8------------------------------------------
[2020-07-18 16:00:23,419] {docker_operator.py:243} INFO - Executing Cell 9---------------------------------------
[2020-07-18 16:00:23,431] {docker_operator.py:243} INFO - Ending Cell 9------------------------------------------
[2020-07-18 16:00:23,441] {docker_operator.py:243} INFO - Executing Cell 10--------------------------------------
[2020-07-18 16:00:23,477] {docker_operator.py:243} INFO - sepal_length  sepal_width  petal_length  petal_width species  \
0           5.1          3.5           1.4          0.2  setosa   
1           4.9          3.0           1.4          0.2  setosa   
2           4.7          3.2           1.3          0.2  setosa   
3           4.6          3.1           1.5          0.2  setosa   
4           5.0          3.6           1.4          0.2  setosa   

                   timestamp  
0 2020-07-18 20:00:23.477063  
1 2020-07-18 20:00:23.477063  
2 2020-07-18 20:00:23.477063  
3 2020-07-18 20:00:23.477063  
4 2020-07-18 20:00:23.477063
[2020-07-18 16:00:23,480] {docker_operator.py:243} INFO - Ending Cell 10-----------------------------------------
[2020-07-18 16:00:23,492] {docker_operator.py:243} INFO - Executing Cell 11--------------------------------------
[2020-07-18 16:00:23,503] {docker_operator.py:243} INFO - Ending Cell 11-----------------------------------------
[2020-07-18 16:00:23,514] {docker_operator.py:243} INFO - Executing Cell 12--------------------------------------
[2020-07-18 16:00:23,526] {docker_operator.py:243} INFO - Ending Cell 12-----------------------------------------
[2020-07-18 16:00:23,537] {docker_operator.py:243} INFO - Executing Cell 13--------------------------------------
[2020-07-18 16:00:23,632] {docker_operator.py:243} INFO - Ending Cell 13-----------------------------------------
[2020-07-18 16:00:24,069] {docker_operator.py:243} INFO - Traceback (most recent call last):
  File "/usr/local/bin/papermill", line 8, in <module>
    sys.exit(papermill())
  File "/usr/local/lib/python3.7/site-packages/click/core.py", line 829, in __call__
    return self.main(*args, **kwargs)
  File "/usr/local/lib/python3.7/site-packages/click/core.py", line 782, in main
    rv = self.invoke(ctx)
  File "/usr/local/lib/python3.7/site-packages/click/core.py", line 1066, in invoke
    return ctx.invoke(self.callback, **ctx.params)
  File "/usr/local/lib/python3.7/site-packages/click/core.py", line 610, in invoke
    return callback(*args, **kwargs)
  File "/usr/local/lib/python3.7/site-packages/papermill/cli.py", line 238, in papermill
    execution_timeout=execution_timeout,
  File "/usr/local/lib/python3.7/site-packages/papermill/execute.py", line 110, in execute_notebook
    raise_for_execution_errors(nb, output_path)
  File "/usr/local/lib/python3.7/site-packages/papermill/execute.py", line 222, in raise_for_execution_errors
    raise error
papermill.exceptions.PapermillExecutionError: 
---------------------------------------------------------------------------
Exception encountered at "In [4]":
---------------------------------------------------------------------------
KeyError                                  Traceback (most recent call last)
<ipython-input-4-acb6e76d29cf> in <module>
----> 1 print(f'the host is:{os.environ["DB_HOST"]}')

/usr/local/lib/python3.7/os.py in __getitem__(self, key)
    679         except KeyError:
    680             # raise KeyError with the original key value
--> 681             raise KeyError(key) from None
    682         return self.decodevalue(value)
    683 

KeyError: 'DB_HOST'
[2020-07-18 16:00:24,305] {taskinstance.py:1150} ERROR - docker container failed: {'Error': None, 'StatusCode': 1}
Traceback (most recent call last):
  File "/Users/mendes/miniconda3/envs/venv-kensho/lib/python3.7/site-packages/airflow/models/taskinstance.py", line 984, in _run_raw_task
    result = task_copy.execute(context=context)
  File "/Users/mendes/miniconda3/envs/venv-kensho/lib/python3.7/site-packages/airflow/operators/docker_operator.py", line 277, in execute
    return self._run_image()
  File "/Users/mendes/miniconda3/envs/venv-kensho/lib/python3.7/site-packages/airflow/operators/docker_operator.py", line 247, in _run_image
    raise AirflowException('docker container failed: ' + repr(result))
airflow.exceptions.AirflowException: docker container failed: {'Error': None, 'StatusCode': 1}
[2020-07-18 16:00:24,308] {taskinstance.py:1194} INFO - Marking task as FAILED. dag_id=etl_preprocessing, task_id=raw-to-db, execution_date=20200718T195834, start_date=20200718T200021, end_date=20200718T200024
[2020-07-18 16:00:24,316] {configuration.py:338} WARNING - section/key [smtp/smtp_user] not found in config
[2020-07-18 16:00:24,318] {configuration.py:338} WARNING - section/key [smtp/smtp_user] not found in config
[2020-07-18 16:00:24,319] {taskinstance.py:1200} ERROR - Failed to send email to: ['info@example.com']
[2020-07-18 16:00:24,319] {taskinstance.py:1201} ERROR - [Errno 61] Connection refused
Traceback (most recent call last):
  File "/Users/mendes/miniconda3/envs/venv-kensho/lib/python3.7/site-packages/airflow/models/taskinstance.py", line 984, in _run_raw_task
    result = task_copy.execute(context=context)
  File "/Users/mendes/miniconda3/envs/venv-kensho/lib/python3.7/site-packages/airflow/operators/docker_operator.py", line 277, in execute
    return self._run_image()
  File "/Users/mendes/miniconda3/envs/venv-kensho/lib/python3.7/site-packages/airflow/operators/docker_operator.py", line 247, in _run_image
    raise AirflowException('docker container failed: ' + repr(result))
airflow.exceptions.AirflowException: docker container failed: {'Error': None, 'StatusCode': 1}

During handling of the above exception, another exception occurred:

Traceback (most recent call last):
  File "/Users/mendes/miniconda3/envs/venv-kensho/lib/python3.7/site-packages/airflow/models/taskinstance.py", line 1473, in email_alert
    send_email(self.task.email, subject, html_content)
  File "/Users/mendes/miniconda3/envs/venv-kensho/lib/python3.7/site-packages/airflow/utils/email.py", line 62, in send_email
    mime_subtype=mime_subtype, mime_charset=mime_charset, **kwargs)
  File "/Users/mendes/miniconda3/envs/venv-kensho/lib/python3.7/site-packages/airflow/utils/email.py", line 108, in send_email_smtp
    send_MIME_email(smtp_mail_from, recipients, msg, dryrun)
  File "/Users/mendes/miniconda3/envs/venv-kensho/lib/python3.7/site-packages/airflow/utils/email.py", line 127, in send_MIME_email
    s = smtplib.SMTP_SSL(SMTP_HOST, SMTP_PORT) if SMTP_SSL else smtplib.SMTP(SMTP_HOST, SMTP_PORT)
  File "/Users/mendes/miniconda3/envs/venv-kensho/lib/python3.7/smtplib.py", line 251, in __init__
    (code, msg) = self.connect(host, port)
  File "/Users/mendes/miniconda3/envs/venv-kensho/lib/python3.7/smtplib.py", line 336, in connect
    self.sock = self._get_socket(host, port, self.timeout)
  File "/Users/mendes/miniconda3/envs/venv-kensho/lib/python3.7/smtplib.py", line 307, in _get_socket
    self.source_address)
  File "/Users/mendes/miniconda3/envs/venv-kensho/lib/python3.7/socket.py", line 728, in create_connection
    raise err
  File "/Users/mendes/miniconda3/envs/venv-kensho/lib/python3.7/socket.py", line 716, in create_connection
    sock.connect(sa)
ConnectionRefusedError: [Errno 61] Connection refused

During handling of the above exception, another exception occurred:

Traceback (most recent call last):
  File "/Users/mendes/miniconda3/envs/venv-kensho/lib/python3.7/site-packages/airflow/models/taskinstance.py", line 1198, in handle_failure
    self.email_alert(error)
  File "/Users/mendes/miniconda3/envs/venv-kensho/lib/python3.7/site-packages/airflow/models/taskinstance.py", line 1475, in email_alert
    send_email(self.task.email, subject, html_content_err)
  File "/Users/mendes/miniconda3/envs/venv-kensho/lib/python3.7/site-packages/airflow/utils/email.py", line 62, in send_email
    mime_subtype=mime_subtype, mime_charset=mime_charset, **kwargs)
  File "/Users/mendes/miniconda3/envs/venv-kensho/lib/python3.7/site-packages/airflow/utils/email.py", line 108, in send_email_smtp
    send_MIME_email(smtp_mail_from, recipients, msg, dryrun)
  File "/Users/mendes/miniconda3/envs/venv-kensho/lib/python3.7/site-packages/airflow/utils/email.py", line 127, in send_MIME_email
    s = smtplib.SMTP_SSL(SMTP_HOST, SMTP_PORT) if SMTP_SSL else smtplib.SMTP(SMTP_HOST, SMTP_PORT)
  File "/Users/mendes/miniconda3/envs/venv-kensho/lib/python3.7/smtplib.py", line 251, in __init__
    (code, msg) = self.connect(host, port)
  File "/Users/mendes/miniconda3/envs/venv-kensho/lib/python3.7/smtplib.py", line 336, in connect
    self.sock = self._get_socket(host, port, self.timeout)
  File "/Users/mendes/miniconda3/envs/venv-kensho/lib/python3.7/smtplib.py", line 307, in _get_socket
    self.source_address)
  File "/Users/mendes/miniconda3/envs/venv-kensho/lib/python3.7/socket.py", line 728, in create_connection
    raise err
  File "/Users/mendes/miniconda3/envs/venv-kensho/lib/python3.7/socket.py", line 716, in create_connection
    sock.connect(sa)
ConnectionRefusedError: [Errno 61] Connection refused
[2020-07-18 16:00:26,306] {local_task_job.py:102} INFO - Task exited with return code 1
